Workbook

Sheet A. General Energy
A1: Energy Management Audit — Section A: General Energy Use & Configuration
A2: Reporting period, tariffs, department-wise energy spend | Yellow = Input | Grey = Auto
A3: Audit Configuration (Used Across All Sheets)
B4: Parameter | D4: Value | F4: Unit | J4: Notes
A5: Reporting Period (Month/Year) | G5: Enter e.g. January 2025
A6: Electricity Tariff | F6: Rs/kWh | G6: Apply to all sheets
A7: Diesel Tariff | F7: Rs/litre | G7: Generator fuel
A8: LPG Tariff | F8: Rs/cylinder (19 kg) | G8: Canteen/hostel
A9: Firewood Tariff | F9: Rs/kg | G9: If applicable
A10: Institution Name
A11: Audit Conducted By
A12: Audit Date
A14: Department / Unit-Wise Energy Spend (Q1–Q7)
A15: S.No. | B15: Department / Unit | C15: Energy Types in Use | D15: Electricity Bill 12-mo (Rs) | E15: LPG Spend 12-mo (Rs) | F15: Firewood/Month (kg) | G15: Firewood Spend/mo (Rs) | H15: Generator Fuel Annual (Rs) | I15: Avg Monthly Spend (Rs) [AUTO] | J15: Energy-Saving Methods? (Y/N)
A16: 1 | I16: =IF(COUNTA(D16:H16)>0,(D16+E16+G16)/12+H16/12,0) -> 0
A17: 2 | I17: =IF(COUNTA(D17:H17)>0,(D17+E17+G17)/12+H17/12,0) -> 0
A18: 3 | I18: =IF(COUNTA(D18:H18)>0,(D18+E18+G18)/12+H18/12,0) -> 0
A19: 4 | I19: =IF(COUNTA(D19:H19)>0,(D19+E19+G19)/12+H19/12,0) -> 0
A20: 5 | I20: =IF(COUNTA(D20:H20)>0,(D20+E20+G20)/12+H20/12,0) -> 0
A21: 6 | I21: =IF(COUNTA(D21:H21)>0,(D21+E21+G21)/12+H21/12,0) -> 0
A22: 7 | I22: =IF(COUNTA(D22:H22)>0,(D22+E22+G22)/12+H22/12,0) -> 0
A23: 8 | I23: =IF(COUNTA(D23:H23)>0,(D23+E23+G23)/12+H23/12,0) -> 0
A24: 9 | I24: =IF(COUNTA(D24:H24)>0,(D24+E24+G24)/12+H24/12,0) -> 0
A25: 10 | I25: =IF(COUNTA(D25:H25)>0,(D25+E25+G25)/12+H25/12,0) -> 0
A26: 11 | I26: =IF(COUNTA(D26:H26)>0,(D26+E26+G26)/12+H26/12,0) -> 0
A27: 12 | I27: =IF(COUNTA(D27:H27)>0,(D27+E27+G27)/12+H27/12,0) -> 0
... A35: 20 | I35: =IF(COUNTA(D35:H35)>0,(D35+E35+G35)/12+H35/12,0) -> 0
A36: TOTALS | D36: =SUM(D16:D35) -> 0 | E36: =SUM(E16:E35) -> 0 | G36: =SUM(G16:G35) -> 0 | H36: =SUM(H16:H35) -> 0 | I36: =SUM(I16:I35) -> 0

Sheet B. Lighting
A1: Section B — Lighting Systems (CFL / LED / Incandescent / Streetlight)
A2: kWh = (Power_W x Qty x Hours/day x Days/month) / 1000 | Cost = kWh x Tariff
A3: S.No. | B3: Location / Building | C3: Type (CFL / LED / Incandescent / Tube / Streetlight) | D3: Power (W) | E3: Quantity | F3: Hours/Day | G3: Days/Month | H3: Energy (kWh/Month) [AUTO] | I3: Cost (Rs/Month) [AUTO] | J3: Notes
A4: 1 | H4: =IF(AND(D4>0,E4>0,F4>0,G4>0),D4*E4*F4*G4/1000,0) -> 0 | I4: =H4*'A. General Energy'!D6 -> 0
A5: 2 | H5: =IF(AND(D5>0,E5>0,F5>0,G5>0),D5*E5*F5*G5/1000,0) -> 0 | I5: =H5*'A. General Energy'!D6 -> 0
A6: 3 | H6: =IF(AND(D6>0,E6>0,F6>0,G6>0),D6*E6*F6*G6/1000,0) -> 0 | I6: =H6*'A. General Energy'!D6 -> 0
A7: 4 | H7: =IF(AND(D7>0,E7>0,F7>0,G7>0),D7*E7*F7*G7/1000,0) -> 0 | I7: =H7*'A. General Energy'!D6 -> 0
A8: 5 | H8: =IF(AND(D8>0,E8>0,F8>0,G8>0),D8*E8*F8*G8/1000,0) -> 0 | I8: =H8*'A. General Energy'!D6 -> 0
A9: 6 | H9: =IF(AND(D9>0,E9>0,F9>0,G9>0),D9*E9*F9*G9/1000,0) -> 0 | I9: =H9*'A. General Energy'!D6 -> 0
A10: 7 | H10: =IF(AND(D10>0,E10>0,F10>0,G10>0),D10*E10*F10*G10/1000,0) -> 0 | I10: =H10*'A. General Energy'!D6 -> 0
A11: 8 | H11: =IF(AND(D11>0,E11>0,F11>0,G11>0),D11*E11*F11*G11/1000,0) -> 0 | I11: =H11*'A. General Energy'!D6 -> 0
A12: 9 | H12: =IF(AND(D12>0,E12>0,F12>0,G12>0),D12*E12*F12*G12/1000,0) -> 0 | I12: =H12*'A. General Energy'!D6 -> 0
A13: 10 | H13: =IF(AND(D13>0,E13>0,F13>0,G13>0),D13*E13*F13*G13/1000,0) -> 0 | I13: =H13*'A. General Energy'!D6 -> 0
A14: 11 | H14: =IF(AND(D14>0,E14>0,F14>0,G14>0),D14*E14*F14*G14/1000,0) -> 0 | I14: =H14*'A. General Energy'!D6 -> 0
A15: 12 | H15: =IF(AND(D15>0,E15>0,F15>0,G15>0),D15*E15*F15*G15/1000,0) -> 0 | I15: =H15*'A. General Energy'!D6 -> 0
A16: 13 | H16: =IF(AND(D16>0,E16>0,F16>0,G16>0),D16*E16*F16*G16/1000,0) -> 0 | I16: =H16*'A. General Energy'!D6 -> 0
A17: 14 | H17: =IF(AND(D17>0,E17>0,F17>0,G17>0),D17*E17*F17*G17/1000,0) -> 0 | I17: =H17*'A. General Energy'!D6 -> 0
A18: 15 | H18: =IF(AND(D18>0,E18>0,F18>0,G18>0),D18*E18*F18*G18/1000,0) -> 0 | I18: =H18*'A. General Energy'!D6 -> 0
A19: 16 | H19: =IF(AND(D19>0,E19>0,F19>0,G19>0),D19*E19*F19*G19/1000,0) -> 0 | I19: =H19*'A. General Energy'!D6 -> 0
A20: 17 | H20: =IF(AND(D20>0,E20>0,F20>0,G20>0),D20*E20*F20*G20/1000,0) -> 0 | I20: =H20*'A. General Energy'!D6 -> 0
A21: 18 | H21: =IF(AND(D21>0,E21>0,F21>0,G21>0),D21*E21*F21*G21/1000,0) -> 0 | I21: =H21*'A. General Energy'!D6 -> 0
A22: 19 | H22: =IF(AND(D22>0,E22>0,F22>0,G22>0),D22*E22*F22*G22/1000,0) -> 0 | I22: =H22*'A. General Energy'!D6 -> 0
A23: 20 | H23: =IF(AND(D23>0,E23>0,F23>0,G23>0),D23*E23*F23*G23/1000,0) -> 0 | I23: =H23*'A. General Energy'!D6 -> 0
A24: 21 | H24: =IF(AND(D24>0,E24>0,F24>0,G24>0),D24*E24*F24*G24/1000,0) -> 0 | I24: =H24*'A. General Energy'!D6 -> 0
A25: 22 | H25: =IF(AND(D25>0,E25>0,F25>0,G25>0),D25*E25*F25*G25/1000,0) -> 0 | I25: =H25*'A. General Energy'!D6 -> 0
A26: 23 | H26: =IF(AND(D26>0,E26>0,F26>0,G26>0),D26*E26*F26*G26/1000,0) -> 0 | I26: =H26*'A. General Energy'!D6 -> 0
A27: 24 | H27: =IF(AND(D27>0,E27>0,F27>0,G27>0),D27*E27*F27*G27/1000,0) -> 0 | I27: =H27*'A. General Energy'!D6 -> 0
A28: 25 | H28: =IF(AND(D28>0,E28>0,F28>0,G28>0),D28*E28*F28*G28/1000,0) -> 0 | I28: =H28*'A. General Energy'!D6 -> 0
A29: 26 | H29: =IF(AND(D29>0,E29>0,F29>0,G29>0),D29*E29*F29*G29/1000,0) -> 0 | I29: =H29*'A. General Energy'!D6 -> 0
A30: 27 | H30: =IF(AND(D30>0,E30>0,F30>0,G30>0),D30*E30*F30*G30/1000,0) -> 0 | I30: =H30*'A. General Energy'!D6 -> 0
A31: 28 | H31: =IF(AND(D31>0,E31>0,F31>0,G31>0),D31*E31*F31*G31/1000,0) -> 0 | I31: =H31*'A. General Energy'!D6 -> 0
A32: 29 | H32: =IF(AND(D32>0,E32>0,F32>0,G32>0),D32*E32*F32*G32/1000,0) -> 0 | I32: =H32*'A. General Energy'!D6 -> 0
A33: 30 | H33: =IF(AND(D33>0,E33>0,F33>0,G33>0),D33*E33*F33*G33/1000,0) -> 0 | I33: =H33*'A. General Energy'!D6 -> 0
A34: 31 | H34: =IF(AND(D34>0,E34>0,F34>0,G34>0),D34*E34*F34*G34/1000,0) -> 0 | I34: =H34*'A. General Energy'!D6 -> 0
A35: 32 | H35: =IF(AND(D35>0,E35>0,F35>0,G35>0),D35*E35*F35*G35/1000,0) -> 0 | I35: =H35*'A. General Energy'!D6 -> 0
A36: 33 | H36: =IF(AND(D36>0,E36>0,F36>0,G36>0),D36*E36*F36*G36/1000,0) -> 0 | I36: =H36*'A. General Energy'!D6 -> 0
A37: 34 | H37: =IF(AND(D37>0,E37>0,F37>0,G37>0),D37*E37*F37*G37/1000,0) -> 0 | I37: =H37*'A. General Energy'!D6 -> 0
A38: 35 | H38: =IF(AND(D38>0,E38>0,F38>0,G38>0),D38*E38*F38*G38/1000,0) -> 0 | I38: =H38*'A. General Energy'!D6 -> 0
A39: 36 | H39: =IF(AND(D39>0,E39>0,F39>0,G39>0),D39*E39*F39*G39/1000,0) -> 0 | I39: =H39*'A. General Energy'!D6 -> 0
A40: 37 | H40: =IF(AND(D40>0,E40>0,F40>0,G40>0),D40*E40*F40*G40/1000,0) -> 0 | I40: =H40*'A. General Energy'!D6 -> 0
...

Sheet C. Fans AC Heating
A1: Section C — Fans, Cooling & Heating Systems
A2: kWh = (W x Qty x Hr/day x Days/mo) / 1000 | Fans, ACs, Coolers, Heaters
A3: S.No. | B3: Location | C3: Type (Fan / AC / Water Cooler / Refrigerator / Heater) | D3: Power (W) | E3: Quantity | F3: Hours/Day | G3: Days/Month | H3: Energy (kWh/Mo) [AUTO] | I3: Cost (Rs/Mo) [AUTO] | J3: Star Rating / Set Temp / Notes
A4: 1 | H4: =IF(AND(D4>0,E4>0,F4>0,G4>0),D4*E4*F4*G4/1000,0) -> 0 | I4: =H4*'A. General Energy'!D6 -> 0
A5: 2 | H5: =IF(AND(D5>0,E5>0,F5>0,G5>0),D5*E5*F5*G5/1000,0) -> 0 | I5: =H5*'A. General Energy'!D6 -> 0
A6: 3 | H6: =IF(AND(D6>0,E6>0,F6>0,G6>0),D6*E6*F6*G6/1000,0) -> 0 | I6: =H6*'A. General Energy'!D6 -> 0
A7: 4 | H7: =IF(AND(D7>0,E7>0,F7>0,G7>0),D7*E7*F7*G7/1000,0) -> 0 | I7: =H7*'A. General Energy'!D6 -> 0
A8: 5 | H8: =IF(AND(D8>0,E8>0,F8>0,G8>0),D8*E8*F8*G8/1000,0) -> 0 | I8: =H8*'A. General Energy'!D6 -> 0
A9: 6 | H9: =IF(AND(D9>0,E9>0,F9>0,G9>0),D9*E9*F9*G9/1000,0) -> 0 | I9: =H9*'A. General Energy'!D6 -> 0
A10: 7 | H10: =IF(AND(D10>0,E10>0,F10>0,G10>0),D10*E10*F10*G10/1000,0) -> 0 | I10: =H10*'A. General Energy'!D6 -> 0
A11: 8 | H11: =IF(AND(D11>0,E11>0,F11>0,G11>0),D11*E11*F11*G11/1000,0) -> 0 | I11: =H11*'A. General Energy'!D6 -> 0
A12: 9 | H12: =IF(AND(D12>0,E12>0,F12>0,G12>0),D12*E12*F12*G12/1000,0) -> 0 | I12: =H12*'A. General Energy'!D6 -> 0
A13: 10 | H13: =IF(AND(D13>0,E13>0,F13>0,G13>0),D13*E13*F13*G13/1000,0) -> 0 | I13: =H13*'A. General Energy'!D6 -> 0
A14: 11 | H14: =IF(AND(D14>0,E14>0,F14>0,G14>0),D14*E14*F14*G14/1000,0) -> 0 | I14: =H14*'A. General Energy'!D6 -> 0
A15: 12 | H15: =IF(AND(D15>0,E15>0,F15>0,G15>0),D15*E15*F15*G15/1000,0) -> 0 | I15: =H15*'A. General Energy'!D6 -> 0
A16: 13 | H16: =IF(AND(D16>0,E16>0,F16>0,G16>0),D16*E16*F16*G16/1000,0) -> 0 | I16: =H16*'A. General Energy'!D6 -> 0
A17: 14 | H17: =IF(AND(D17>0,E17>0,F17>0,G17>0),D17*E17*F17*G17/1000,0) -> 0 | I17: =H17*'A. General Energy'!D6 -> 0
A18: 15 | H18: =IF(AND(D18>0,E18>0,F18>0,G18>0),D18*E18*F18*G18/1000,0) -> 0 | I18: =H18*'A. General Energy'!D6 -> 0
A19: 16 | H19: =IF(AND(D19>0,E19>0,F19>0,G19>0),D19*E19*F19*G19/1000,0) -> 0 | I19: =H19*'A. General Energy'!D6 -> 0
A20: 17 | H20: =IF(AND(D20>0,E20>0,F20>0,G20>0),D20*E20*F20*G20/1000,0) -> 0 | I20: =H20*'A. General Energy'!D6 -> 0
A21: 18 | H21: =IF(AND(D21>0,E21>0,F21>0,G21>0),D21*E21*F21*G21/1000,0) -> 0 | I21: =H21*'A. General Energy'!D6 -> 0
A22: 19 | H22: =IF(AND(D22>0,E22>0,F22>0,G22>0),D22*E22*F22*G22/1000,0) -> 0 | I22: =H22*'A. General Energy'!D6 -> 0
A23: 20 | H23: =IF(AND(D23>0,E23>0,F23>0,G23>0),D23*E23*F23*G23/1000,0) -> 0 | I23: =H23*'A. General Energy'!D6 -> 0
A24: 21 | H24: =IF(AND(D24>0,E24>0,F24>0,G24>0),D24*E24*F24*G24/1000,0) -> 0 | I24: =H24*'A. General Energy'!D6 -> 0
A25: 22 | H25: =IF(AND(D25>0,E25>0,F25>0,G25>0),D25*E25*F25*G25/1000,0) -> 0 | I25: =H25*'A. General Energy'!D6 -> 0
A26: 23 | H26: =IF(AND(D26>0,E26>0,F26>0,G26>0),D26*E26*F26*G26/1000,0) -> 0 | I26: =H26*'A. General Energy'!D6 -> 0
A27: 24 | H27: =IF(AND(D27>0,E27>0,F27>0,G27>0),D27*E27*F27*G27/1000,0) -> 0 | I27: =H27*'A. General Energy'!D6 -> 0
A28: 25 | H28: =IF(AND(D28>0,E28>0,F28>0,G28>0),D28*E28*F28*G28/1000,0) -> 0 | I28: =H28*'A. General Energy'!D6 -> 0
A29: 26 | H29: =IF(AND(D29>0,E29>0,F29>0,G29>0),D29*E29*F29*G29/1000,0) -> 0 | I29: =H29*'A. General Energy'!D6 -> 0
A30: 27 | H30: =IF(AND(D30>0,E30>0,F30>0,G30>0),D30*E30*F30*G30/1000,0) -> 0 | I30: =H30*'A. General Energy'!D6 -> 0
A31: 28 | H31: =IF(AND(D31>0,E31>0,F31>0,G31>0),D31*E31*F31*G31/1000,0) -> 0 | I31: =H31*'A. General Energy'!D6 -> 0
A32: 29 | H32: =IF(AND(D32>0,E32>0,F32>0,G32>0),D32*E32*F32*G32/1000,0) -> 0 | I32: =H32*'A. General Energy'!D6 -> 0
A33: 30 | H33: =IF(AND(D33>0,E33>0,F33>0,G33>0),D33*E33*F33*G33/1000,0) -> 0 | I33: =H33*'A. General Energy'!D6 -> 0
A34: 31 | H34: =IF(AND(D34>0,E34>0,F34>0,G34>0),D34*E34*F34*G34/1000,0) -> 0 | I34: =H34*'A. General Energy'!D6 -> 0
A35: 32 | H35: =IF(AND(D35>0,E35>0,F35>0,G35>0),D35*E35*F35*G35/1000,0) -> 0 | I35: =H35*'A. General Energy'!D6 -> 0
A36: 33 | H36: =IF(AND(D36>0,E36>0,F36>0,G36>0),D36*E36*F36*G36/1000,0) -> 0 | I36: =H36*'A. General Energy'!D6 -> 0
A37: 34 | H37: =IF(AND(D37>0,E37>0,F37>0,G37>0),D37*E37*F37*G37/1000,0) -> 0 | I37: =H37*'A. General Energy'!D6 -> 0
A38: 35 | H38: =IF(AND(D38>0,E38>0,F38>0,G38>0),D38*E38*F38*G38/1000,0) -> 0 | I38: =H38*'A. General Energy'!D6 -> 0
A39: 36 | H39: =IF(AND(D39>0,E39>0,F39>0,G39>0),D39*E39*F39*G39/1000,0) -> 0 | I39: =H39*'A. General Energy'!D6 -> 0
A40: 37 | H40: =IF(AND(D40>0,E40>0,F40>0,G40>0),D40*E40*F40*G40/1000,0) -> 0 | I40: =H40*'A. General Energy'!D6 -> 0
...

Sheet D. ICT & Office
A1: Section D — ICT and Office Equipment
A2: Computers, Printers, Photocopiers, Projectors, TVs, Inverters + Standby & Power-Save Mode
A3: S.No. | B3: Location / Dept | C3: Type (Computer / Printer / Photocopier / Projector / TV / Inverter / Other) | D3: Power (W) | E3: Quantity | F3: Hours/Day | G3: Days/Month | H3: Energy (kWh/Mo) [AUTO] | I3: Cost (Rs/Mo) [AUTO] | J3: Standby Hr/Day | K3: Power-Save Mode (Y/N) | L3: Notes
A4: 1 | H4: =IF(AND(D4>0,E4>0,F4>0,G4>0),D4*E4*F4*G4/1000,0) -> 0 | I4: =H4*'A. General Energy'!D6 -> 0
A5: 2 | H5: =IF(AND(D5>0,E5>0,F5>0,G5>0),D5*E5*F5*G5/1000,0) -> 0 | I5: =H5*'A. General Energy'!D6 -> 0
A6: 3 | H6: =IF(AND(D6>0,E6>0,F6>0,G6>0),D6*E6*F6*G6/1000,0) -> 0 | I6: =H6*'A. General Energy'!D6 -> 0
A7: 4 | H7: =IF(AND(D7>0,E7>0,F7>0,G7>0),D7*E7*F7*G7/1000,0) -> 0 | I7: =H7*'A. General Energy'!D6 -> 0
A8: 5 | H8: =IF(AND(D8>0,E8>0,F8>0,G8>0),D8*E8*F8*G8/1000,0) -> 0 | I8: =H8*'A. General Energy'!D6 -> 0
A9: 6 | H9: =IF(AND(D9>0,E9>0,F9>0,G9>0),D9*E9*F9*G9/1000,0) -> 0 | I9: =H9*'A. General Energy'!D6 -> 0
A10: 7 | H10: =IF(AND(D10>0,E10>0,F10>0,G10>0),D10*E10*F10*G10/1000,0) -> 0 | I10: =H10*'A. General Energy'!D6 -> 0
A11: 8 | H11: =IF(AND(D11>0,E11>0,F11>0,G11>0),D11*E11*F11*G11/1000,0) -> 0 | I11: =H11*'A. General Energy'!D6 -> 0
A12: 9 | H12: =IF(AND(D12>0,E12>0,F12>0,G12>0),D12*E12*F12*G12/1000,0) -> 0 | I12: =H12*'A. General Energy'!D6 -> 0
A13: 10 | H13: =IF(AND(D13>0,E13>0,F13>0,G13>0),D13*E13*F13*G13/1000,0) -> 0 | I13: =H13*'A. General Energy'!D6 -> 0
A14: 11 | H14: =IF(AND(D14>0,E14>0,F14>0,G14>0),D14*E14*F14*G14/1000,0) -> 0 | I14: =H14*'A. General Energy'!D6 -> 0
A15: 12 | H15: =IF(AND(D15>0,E15>0,F15>0,G15>0),D15*E15*F15*G15/1000,0) -> 0 | I15: =H15*'A. General Energy'!D6 -> 0
A16: 13 | H16: =IF(AND(D16>0,E16>0,F16>0,G16>0),D16*E16*F16*G16/1000,0) -> 0 | I16: =H16*'A. General Energy'!D6 -> 0
A17: 14 | H17: =IF(AND(D17>0,E17>0,F17>0,G17>0),D17*E17*F17*G17/1000,0) -> 0 | I17: =H17*'A. General Energy'!D6 -> 0
A18: 15 | H18: =IF(AND(D18>0,E18>0,F18>0,G18>0),D18*E18*F18*G18/1000,0) -> 0 | I18: =H18*'A. General Energy'!D6 -> 0
A19: 16 | H19: =IF(AND(D19>0,E19>0,F19>0,G19>0),D19*E19*F19*G19/1000,0) -> 0 | I19: =H19*'A. General Energy'!D6 -> 0
A20: 17 | H20: =IF(AND(D20>0,E20>0,F20>0,G20>0),D20*E20*F20*G20/1000,0) -> 0 | I20: =H20*'A. General Energy'!D6 -> 0
A21: 18 | H21: =IF(AND(D21>0,E21>0,F21>0,G21>0),D21*E21*F21*G21/1000,0) -> 0 | I21: =H21*'A. General Energy'!D6 -> 0
A22: 19 | H22: =IF(AND(D22>0,E22>0,F22>0,G22>0),D22*E22*F22*G22/1000,0) -> 0 | I22: =H22*'A. General Energy'!D6 -> 0
A23: 20 | H23: =IF(AND(D23>0,E23>0,F23>0,G23>0),D23*E23*F23*G23/1000,0) -> 0 | I23: =H23*'A. General Energy'!D6 -> 0
A24: 21 | H24: =IF(AND(D24>0,E24>0,F24>0,G24>0),D24*E24*F24*G24/1000,0) -> 0 | I24: =H24*'A. General Energy'!D6 -> 0
A25: 22 | H25: =IF(AND(D25>0,E25>0,F25>0,G25>0),D25*E25*F25*G25/1000,0) -> 0 | I25: =H25*'A. General Energy'!D6 -> 0
A26: 23 | H26: =IF(AND(D26>0,E26>0,F26>0,G26>0),D26*E26*F26*G26/1000,0) -> 0 | I26: =H26*'A. General Energy'!D6 -> 0
A27: 24 | H27: =IF(AND(D27>0,E27>0,F27>0,G27>0),D27*E27*F27*G27/1000,0) -> 0 | I27: =H27*'A. General Energy'!D6 -> 0
A28: 25 | H28: =IF(AND(D28>0,E28>0,F28>0,G28>0),D28*E28*F28*G28/1000,0) -> 0 | I28: =H28*'A. General Energy'!D6 -> 0
A29: 26 | H29: =IF(AND(D29>0,E29>0,F29>0,G29>0),D29*E29*F29*G29/1000,0) -> 0 | I29: =H29*'A. General Energy'!D6 -> 0
A30: 27 | H30: =IF(AND(D30>0,E30>0,F30>0,G30>0),D30*E30*F30*G30/1000,0) -> 0 | I30: =H30*'A. General Energy'!D6 -> 0
A31: 28 | H31: =IF(AND(D31>0,E31>0,F31>0,G31>0),D31*E31*F31*G31/1000,0) -> 0 | I31: =H31*'A. General Energy'!D6 -> 0
A32: 29 | H32: =IF(AND(D32>0,E32>0,F32>0,G32>0),D32*E32*F32*G32/1000,0) -> 0 | I32: =H32*'A. General Energy'!D6 -> 0
A33: 30 | H33: =IF(AND(D33>0,E33>0,F33>0,G33>0),D33*E33*F33*G33/1000,0) -> 0 | I33: =H33*'A. General Energy'!D6 -> 0
A34: 31 | H34: =IF(AND(D34>0,E34>0,F34>0,G34>0),D34*E34*F34*G34/1000,0) -> 0 | I34: =H34*'A. General Energy'!D6 -> 0
A35: 32 | H35: =IF(AND(D35>0,E35>0,F35>0,G35>0),D35*E35*F35*G35/1000,0) -> 0 | I35: =H35*'A. General Energy'!D6 -> 0
A36: 33 | H36: =IF(AND(D36>0,E36>0,F36>0,G36>0),D36*E36*F36*G36/1000,0) -> 0 | I36: =H36*'A. General Energy'!D6 -> 0
A37: 34 | H37: =IF(AND(D37>0,E37>0,F37>0,G37>0),D37*E37*F37*G37/1000,0) -> 0 | I37: =H37*'A. General Energy'!D6 -> 0
A38: 35 | H38: =IF(AND(D38>0,E38>0,F38>0,G38>0),D38*E38*F38*G38/1000,0) -> 0 | I38: =H38*'A. General Energy'!D6 -> 0
A39: 36 | H39: =IF(AND(D39>0,E39>0,F39>0,G39>0),D39*E39*F39*G39/1000,0) -> 0 | I39: =H39*'A. General Energy'!D6 -> 0
A40: 37 | H40: =IF(AND(D40>0,E40>0,F40>0,G40>0),D40*E40*F40*G40/1000,0) -> 0 | I40: =H40*'A. General Energy'!D6 -> 0
...

Sheet E. Laboratory
A1: Section E — Laboratory Equipment Energy Consumption
A2: All lab instruments: microscopes, centrifuges, ovens, spectrophotometers, etc.
A3: S.No. | B3: Lab Name | C3: Equipment | D3: Power (W) | E3: Quantity | F3: Hours/Day | G3: Days/Month | H3: Energy (kWh/Mo) [AUTO] | I3: Cost (Rs/Mo) [AUTO] | J3: Notes
A4: 1 | H4: =IF(AND(D4>0,E4>0,F4>0,G4>0),D4*E4*F4*G4/1000,0) -> 0 | I4: =H4*'A. General Energy'!D6 -> 0
A5: 2 | H5: =IF(AND(D5>0,E5>0,F5>0,G5>0),D5*E5*F5*G5/1000,0) -> 0 | I5: =H5*'A. General Energy'!D6 -> 0
A6: 3 | H6: =IF(AND(D6>0,E6>0,F6>0,G6>0),D6*E6*F6*G6/1000,0) -> 0 | I6: =H6*'A. General Energy'!D6 -> 0
A7: 4 | H7: =IF(AND(D7>0,E7>0,F7>0,G7>0),D7*E7*F7*G7/1000,0) -> 0 | I7: =H7*'A. General Energy'!D6 -> 0
A8: 5 | H8: =IF(AND(D8>0,E8>0,F8>0,G8>0),D8*E8*F8*G8/1000,0) -> 0 | I8: =H8*'A. General Energy'!D6 -> 0
A9: 6 | H9: =IF(AND(D9>0,E9>0,F9>0,G9>0),D9*E9*F9*G9/1000,0) -> 0 | I9: =H9*'A. General Energy'!D6 -> 0
A10: 7 | H10: =IF(AND(D10>0,E10>0,F10>0,G10>0),D10*E10*F10*G10/1000,0) -> 0 | I10: =H10*'A. General Energy'!D6 -> 0
A11: 8 | H11: =IF(AND(D11>0,E11>0,F11>0,G11>0),D11*E11*F11*G11/1000,0) -> 0 | I11: =H11*'A. General Energy'!D6 -> 0
A12: 9 | H12: =IF(AND(D12>0,E12>0,F12>0,G12>0),D12*E12*F12*G12/1000,0) -> 0 | I12: =H12*'A. General Energy'!D6 -> 0
A13: 10 | H13: =IF(AND(D13>0,E13>0,F13>0,G13>0),D13*E13*F13*G13/1000,0) -> 0 | I13: =H13*'A. General Energy'!D6 -> 0
A14: 11 | H14: =IF(AND(D14>0,E14>0,F14>0,G14>0),D14*E14*F14*G14/1000,0) -> 0 | I14: =H14*'A. General Energy'!D6 -> 0
A15: 12 | H15: =IF(AND(D15>0,E15>0,F15>0,G15>0),D15*E15*F15*G15/1000,0) -> 0 | I15: =H15*'A. General Energy'!D6 -> 0
A16: 13 | H16: =IF(AND(D16>0,E16>0,F16>0,G16>0),D16*E16*F16*G16/1000,0) -> 0 | I16: =H16*'A. General Energy'!D6 -> 0
A17: 14 | H17: =IF(AND(D17>0,E17>0,F17>0,G17>0),D17*E17*F17*G17/1000,0) -> 0 | I17: =H17*'A. General Energy'!D6 -> 0
A18: 15 | H18: =IF(AND(D18>0,E18>0,F18>0,G18>0),D18*E18*F18*G18/1000,0) -> 0 | I18: =H18*'A. General Energy'!D6 -> 0
A19: 16 | H19: =IF(AND(D19>0,E19>0,F19>0,G19>0),D19*E19*F19*G19/1000,0) -> 0 | I19: =H19*'A. General Energy'!D6 -> 0
A20: 17 | H20: =IF(AND(D20>0,E20>0,F20>0,G20>0),D20*E20*F20*G20/1000,0) -> 0 | I20: =H20*'A. General Energy'!D6 -> 0
A21: 18 | H21: =IF(AND(D21>0,E21>0,F21>0,G21>0),D21*E21*F21*G21/1000,0) -> 0 | I21: =H21*'A. General Energy'!D6 -> 0
A22: 19 | H22: =IF(AND(D22>0,E22>0,F22>0,G22>0),D22*E22*F22*G22/1000,0) -> 0 | I22: =H22*'A. General Energy'!D6 -> 0
A23: 20 | H23: =IF(AND(D23>0,E23>0,F23>0,G23>0),D23*E23*F23*G23/1000,0) -> 0 | I23: =H23*'A. General Energy'!D6 -> 0
A24: 21 | H24: =IF(AND(D24>0,E24>0,F24>0,G24>0),D24*E24*F24*G24/1000,0) -> 0 | I24: =H24*'A. General Energy'!D6 -> 0
A25: 22 | H25: =IF(AND(D25>0,E25>0,F25>0,G25>0),D25*E25*F25*G25/1000,0) -> 0 | I25: =H25*'A. General Energy'!D6 -> 0
A26: 23 | H26: =IF(AND(D26>0,E26>0,F26>0,G26>0),D26*E26*F26*G26/1000,0) -> 0 | I26: =H26*'A. General Energy'!D6 -> 0
A27: 24 | H27: =IF(AND(D27>0,E27>0,F27>0,G27>0),D27*E27*F27*G27/1000,0) -> 0 | I27: =H27*'A. General Energy'!D6 -> 0
A28: 25 | H28: =IF(AND(D28>0,E28>0,F28>0,G28>0),D28*E28*F28*G28/1000,0) -> 0 | I28: =H28*'A. General Energy'!D6 -> 0
A29: 26 | H29: =IF(AND(D29>0,E29>0,F29>0,G29>0),D29*E29*F29*G29/1000,0) -> 0 | I29: =H29*'A. General Energy'!D6 -> 0
A30: 27 | H30: =IF(AND(D30>0,E30>0,F30>0,G30>0),D30*E30*F30*G30/1000,0) -> 0 | I30: =H30*'A. General Energy'!D6 -> 0
A31: 28 | H31: =IF(AND(D31>0,E31>0,F31>0,G31>0),D31*E31*F31*G31/1000,0) -> 0 | I31: =H31*'A. General Energy'!D6 -> 0
A32: 29 | H32: =IF(AND(D32>0,E32>0,F32>0,G32>0),D32*E32*F32*G32/1000,0) -> 0 | I32: =H32*'A. General Energy'!D6 -> 0
A33: 30 | H33: =IF(AND(D33>0,E33>0,F33>0,G33>0),D33*E33*F33*G33/1000,0) -> 0 | I33: =H33*'A. General Energy'!D6 -> 0
A34: 31 | H34: =IF(AND(D34>0,E34>0,F34>0,G34>0),D34*E34*F34*G34/1000,0) -> 0 | I34: =H34*'A. General Energy'!D6 -> 0
A35: 32 | H35: =IF(AND(D35>0,E35>0,F35>0,G35>0),D35*E35*F35*G35/1000,0) -> 0 | I35: =H35*'A. General Energy'!D6 -> 0
A36: 33 | H36: =IF(AND(D36>0,E36>0,F36>0,G36>0),D36*E36*F36*G36/1000,0) -> 0 | I36: =H36*'A. General Energy'!D6 -> 0
A37: 34 | H37: =IF(AND(D37>0,E37>0,F37>0,G37>0),D37*E37*F37*G37/1000,0) -> 0 | I37: =H37*'A. General Energy'!D6 -> 0
A38: 35 | H38: =IF(AND(D38>0,E38>0,F38>0,G38>0),D38*E38*F38*G38/1000,0) -> 0 | I38: =H38*'A. General Energy'!D6 -> 0
A39: 36 | H39: =IF(AND(D39>0,E39>0,F39>0,G39>0),D39*E39*F39*G39/1000,0) -> 0 | I39: =H39*'A. General Energy'!D6 -> 0
A40: 37 | H40: =IF(AND(D40>0,E40>0,F40>0,G40>0),D40*E40*F40*G40/1000,0) -> 0 | I40: =H40*'A. General Energy'!D6 -> 0
...

Sheet F. Alt Energy & Conservation
A1: Section F — Alternative Energy Sources & Conservation Practices
A2: Solar, Wind, Biogas, Energy-Efficient Stoves + Switch-Off Drills + Power-Save + Awareness
A3: S.No. | B3: Type (Solar PV / Solar Water / Wind / Biogas / Other) | C3: Capacity (kW or LPD) | D3: Monthly Generation (kWh) | E3: Diesel Saved (L/Mo) | F3: LPG Saved (kg/Mo) | G3: Equiv. Cost Saved (Rs/Mo) [AUTO] | H3: Switch-Off Drills? (Y/N) | I3: Power-Save Mode? (Y/N) | J3: Avg Standby Hr/Day | K3: Awareness Boards Count
A4: 1 | G4: =D4*'A. General Energy'!D6+E4*'A. General Energy'!D7+F4*'A. General Energy'!D8/19 -> 0
A5: 2 | G5: =D5*'A. General Energy'!D6+E5*'A. General Energy'!D7+F5*'A. General Energy'!D8/19 -> 0
A6: 3 | G6: =D6*'A. General Energy'!D6+E6*'A. General Energy'!D7+F6*'A. General Energy'!D8/19 -> 0
A7: 4 | G7: =D7*'A. General Energy'!D6+E7*'A. General Energy'!D7+F7*'A. General Energy'!D8/19 -> 0
A8: 5 | G8: =D8*'A. General Energy'!D6+E8*'A. General Energy'!D7+F8*'A. General Energy'!D8/19 -> 0
A9: 6 | G9: =D9*'A. General Energy'!D6+E9*'A. General Energy'!D7+F9*'A. General Energy'!D8/19 -> 0
A10: 7 | G10: =D10*'A. General Energy'!D6+E10*'A. General Energy'!D7+F10*'A. General Energy'!D8/19 -> 0
A11: 8 | G11: =D11*'A. General Energy'!D6+E11*'A. General Energy'!D7+F11*'A. General Energy'!D8/19 -> 0
A12: 9 | G12: =D12*'A. General Energy'!D6+E12*'A. General Energy'!D7+F12*'A. General Energy'!D8/19 -> 0
A13: 10 | G13: =D13*'A. General Energy'!D6+E13*'A. General Energy'!D7+F13*'A. General Energy'!D8/19 -> 0
A14: 11 | G14: =D14*'A. General Energy'!D6+E14*'A. General Energy'!D7+F14*'A. General Energy'!D8/19 -> 0
A15: 12 | G15: =D15*'A. General Energy'!D6+E15*'A. General Energy'!D7+F15*'A. General Energy'!D8/19 -> 0
A16: 13 | G16: =D16*'A. General Energy'!D6+E16*'A. General Energy'!D7+F16*'A. General Energy'!D8/19 -> 0
A17: 14 | G17: =D17*'A. General Energy'!D6+E17*'A. General Energy'!D7+F17*'A. General Energy'!D8/19 -> 0
A18: 15 | G18: =D18*'A. General Energy'!D6+E18*'A. General Energy'!D7+F18*'A. General Energy'!D8/19 -> 0
A19: Section F Totals
A20: TOTAL ALT ENERGY | D20: =SUM(D4:D18) -> 0 | G20: =SUM(G4:G18) -> 0

Sheet G. Waste & By-products
A1: Section G — Waste & By-Products (Ash, Biomass Residue)
A2: Firewood ash, waste-to-energy links | For context alongside energy audit
A3: S.No. | B3: Source (Canteen / Boiler / Other) | C3: Ash per Day (kg) | D3: Days/Month | E3: Monthly Ash (kg) [AUTO] | F3: Disposal Method / Notes
A4: 1 | E4: =IF(AND(C4>0,D4>0),C4*D4,0) -> 0
A5: 2 | E5: =IF(AND(C5>0,D5>0),C5*D5,0) -> 0
A6: 3 | E6: =IF(AND(C6>0,D6>0),C6*D6,0) -> 0
A7: 4 | E7: =IF(AND(C7>0,D7>0),C7*D7,0) -> 0
A8: 5 | E8: =IF(AND(C8>0,D8>0),C8*D8,0) -> 0
A9: 6 | E9: =IF(AND(C9>0,D9>0),C9*D9,0) -> 0
A10: 7 | E10: =IF(AND(C10>0,D10>0),C10*D10,0) -> 0
A11: 8 | E11: =IF(AND(C11>0,D11>0),C11*D11,0) -> 0
A12: 9 | E12: =IF(AND(C12>0,D12>0),C12*D12,0) -> 0
A13: 10 | E13: =IF(AND(C13>0,D13>0),C13*D13,0) -> 0
A14: TOTAL ASH / MONTH (kg) | E14: =SUM(E4:E13) -> 0

Sheet H. Energy Dashboard
A1: ENERGY AUDIT DASHBOARD — Auto-Calculated Summary Across All Sections
A2: All values auto-linked from Section A–G sheets | Net consumption + cost + renewable offset
A3: S.No. | B3: Category | C3: kWh / Month | D3: Cost (Rs/Month) | E3: % of Total kWh | F3: % of Total Cost | G3: Notes
A4: 1 | B4: B — Lighting | C4: ='B. Lighting'!H55 -> 0 | D4: ='B. Lighting'!I55 -> 0 | E4: =IF(C10>0,C4/C10*100,0) -> 0 | F4: =IF(D10>0,D4/D10*100,0) -> 0 | G4: Section B total
A5: 2 | B5: C — Fans / AC / Heating | C5: ='C. Fans AC Heating'!H55 -> 0 | D5: ='C. Fans AC Heating'!I55 -> 0 | E5: =IF(C10>0,C5/C10*100,0) -> 0 | F5: =IF(D10>0,D5/D10*100,0) -> 0 | G5: Section C total
A6: 3 | B6: D — ICT & Office Equipment | C6: ='D. ICT & Office'!H55 -> 0 | D6: ='D. ICT & Office'!I55 -> 0 | E6: =IF(C10>0,C6/C10*100,0) -> 0 | F6: =IF(D10>0,D6/D10*100,0) -> 0 | G6: Section D total
A7: 4 | B7: E — Laboratory Equipment | C7: ='E. Laboratory'!H55 -> 0 | D7: ='E. Laboratory'!I55 -> 0 | E7: =IF(C10>0,C7/C10*100,0) -> 0 | F7: =IF(D10>0,D7/D10*100,0) -> 0 | G7: Section E total
A8: 5 | B8: F — Alt Energy Savings (kWh equiv.) | C8: ='F. Alt Energy & Conservation'!D20 -> 0 | D8: ='F. Alt Energy & Conservation'!G20 -> 0 | G8: Generation + savings
A9: 6 | B9: G — Waste / By-products (kg ash/mo) | C9: ='G. Waste & By-products'!E14 -> 0 | G9: Not energy; for context
A10: GROSS ELECTRICITY (kWh/Month) — Sections B+C+D+E | C10: =C4+C5+C6+C7 -> 0 | D10: =D4+D5+D6+D7 -> 0
A11: NET ELECTRICITY (Gross − Solar/Alt Generation) | C11: =IF(C10>C8,C10-C8,0) -> 0 | D11: =IF(D10>D8,D10-D8,0) -> 0
A12: Renewable Offset (% of Gross) | C12: =IF(C10>0,C8/C10*100,0) -> 0
A14: Key Energy Observations (Auto-Populated from Sections)
A15: Total Lighting Fixtures | C15: ='B. Lighting'!E55 -> 0 | D15: Nos.
A16: LED Transition % | C16: ='B. Lighting'!E64 -> 0 | D16: %
A17: Total Fans | C17: ='C. Fans AC Heating'!E57 -> 0 | D17: Nos.
A18: Total ACs | C18: ='C. Fans AC Heating'!E58 -> 0 | D18: Nos.
A19: Total Computers | C19: ='D. ICT & Office'!E55 -> 0 | D19: Nos. (all ICT)
A20: Solar / Alt Generation (kWh/mo) | C20: ='F. Alt Energy & Conservation'!D20 -> 0 | D20: kWh
A21: Monthly Ash Generated (kg) | C21: ='G. Waste & By-products'!E14 -> 0 | D21: kg

Sheet I. Audit Checklist
A1: Energy Audit — Compliance Checklist & Future Suggestions (NAAC / Green Audit)
A2: Sections A–H evidence + conservation practices + future planning
A3: # | B3: Audit Item | C3: Requirement / Description | D3: Status (Y/X/IP) | E3: Date | F3: Reviewer
A4: 1 | B4: General energy data complete | C4: All energy types listed; 12-month bills, LPG, firewood, generator fuel documented
A5: 2 | B5: Tariffs configured | C5: Electricity (Rs/kWh), diesel, LPG tariffs entered in Config sheet
A6: 3 | B6: Lighting inventory complete | C6: All CFL/LED/incandescent/tube/streetlights with W, qty, hours, days entered
A7: 4 | B7: LED transition % calculated | C7: % of total fixtures that are LED; target >=80% for green campus
A8: 5 | B8: Fans/AC/cooling complete | C8: All fans, ACs, coolers, heaters with ratings and usage documented
A9: 6 | B9: AC star ratings documented | C9: BEE star rating and set temperature for all ACs noted
A10: 7 | B10: ICT equipment complete | C10: Computers, printers, photocopiers, projectors, TVs, inverters documented
A11: 8 | B11: Standby hours tracked | C11: Standby mode hours per day documented for ICT equipment
A12: 9 | B12: Power-save mode checked | C12: Y/N for power-save mode on computers and equipment
A13: 10 | B13: Lab equipment documented | C13: All lab instruments with power rating and usage pattern listed
A14: 11 | B14: Alternative energy documented | C14: Solar PV, solar water heater, wind, biogas capacity and generation
A15: 12 | B15: Switch-off drills conducted | C15: Evidence of energy-saving drills in classrooms/labs
... A23: 20 | B23: Reproducibility verified | C23: All calculations reproducible from input data
