Workbook

Sheet 1. Source Reference
A1: Institutional Wastewater Generation — Source Classification & Management Guide
A2: 6 Source Categories | Grey / Black / RO / Lab Classification | STP / ETP Routing | NAAC 7.1.4
A3: # | B3: Source Category | C3: Specific Sources | D3: Wastewater Type | E3: Treatment Route | F3: Reuse Potential
A4: 1 | B4: Academic Departments | C4: Lab washbasins, hand-wash areas, floor cleaning, equipment rinse | D4: Grey water (soaps, detergents, diluted chemicals) | E4: Lab waste → neutralization → ETP; General → STP | F4: Floor cleaning, gardening (after treatment)
A5: 2 | B5: Canteen & Mess | C5: Dishwashing, food preparation, floor cleaning, hand-wash | D5: Grey water with high organic load (food particles, oils, detergents) | E5: Grease trap → STP / ETP | F5: Non-potable: flushing, cleaning (after treatment)
A6: 3 | B6: Washrooms & Toilets | C6: Toilets, urinals, washbasins | D6: Black water (sewage, high bacterial load) | E6: Direct to STP → disinfection | F6: Flushing, gardening (after full treatment)
A7: 4 | B7: Hostels & Residential | C7: Bathrooms, laundry, toilets, handwash | D7: Mix of grey + black water | E7: Grey water separated → reuse; Black → STP | F7: Laundry rinse reuse, gardening, flushing
A8: 5 | B8: RO Plant Reject | C8: Drinking water purification reject streams | D8: High TDS water (salts, minerals) | E8: Separate tank → dilute with grey water → ETP | F8: Gardening, floor cleaning, cooling towers
A9: 6 | B9: Gardening & Outdoor | C9: Overflow, pavement washing, cleaning water | D9: Grey water with soil, mud, organic matter | E9: Recharge pits or filtered for reuse | F9: Ground recharge, irrigation recycling
A11: Proposed Treatment Strategy
A12: # | B12: System | C12: Function | D12: Input Sources | E12: Output Quality | F12: Reuse Applications
A13: 1 | B13: STP (Sewage Treatment Plant) | C13: Treats black water and general grey water to discharge/reuse standards | D13: Toilets, urinals, canteen sewage, hostel sewage, general grey water | E13: BOD <10 mg/L, TSS <10 mg/L, pH 6.5–8.5 | F13: Gardening, flushing, landscape irrigation, construction
A14: 2 | B14: ETP (Effluent Treatment Plant) | C14: Treats high organic load, chemical-laden, and high-TDS wastewater | D14: RO reject, lab wastewater (after neutralization), canteen grease-trap effluent | E14: Meets CPCB discharge norms; suitable for controlled reuse | F14: Floor cleaning, cooling towers, diluted gardening
A15: 3 | B15: Sludge Composting | C15: Converts STP/ETP sludge to organic fertilizer | D15: Sludge from STP settling tanks and ETP filter press | E15: Stabilized compost; pathogen-free after 60-day maturation | F15: Campus garden fertilizer, nursery beds, landscaping

Sheet 2. Sources Log
A1: Wastewater Sources Log — Daily Generation by Location & Type
A2: Enter every source: category, location, type, volume (L/day), routing → feeds Treatment & Dashboard
A3: S.No. | B3: Date / Period | C3: Source Category | D3: Location / Block | E3: Wastewater Type (Grey / Black / RO / Lab) | F3: Estimated Volume (L/day) | G3: Collection Tank ID | H3: Routed To (STP / ETP / Recharge Pit) | I3: Measurement Method (Meter / Estimate / Formula) | J3: Remarks
A4: 1 | C4: Academic Dept | D4: Science Lab Complex | E4: Lab | F4: 150 | G4: CT-LAB-01 | H4: ETP | I4: Estimate | J4: Neutralized before routing
A5: 2 | C5: Academic Dept | D5: Academic Block 1 Washbasins | E5: Grey | F5: 200 | G5: CT-AB1 | H5: STP | I5: Estimate
A6: 3 | C6: Academic Dept | D6: Academic Block 2 Washbasins | E6: Grey | F6: 180 | G6: CT-AB2 | H6: STP | I6: Estimate
A7: 4 | C7: Academic Dept | D7: Workshop / Engineering Lab | E7: Grey | F7: 100 | G7: CT-WS1 | H7: STP | I7: Estimate | J7: Coolant water included
A8: 5 | C8: Canteen & Mess | D8: Main Canteen Kitchen | E8: Grey | F8: 500 | G8: CT-CAN-01 | H8: STP | I8: Meter | J8: Via grease trap
A9: 6 | C9: Canteen & Mess | D9: Hostel Mess Kitchen | E9: Grey | F9: 400 | G9: CT-MES-01 | H9: STP | I9: Meter | J9: Via grease trap
A10: 7 | C10: Washrooms & Toilets | D10: Academic Block Washrooms | E10: Black | F10: 800 | G10: CT-WR-01 | H10: STP | I10: Formula | J10: Population × 15L
A11: 8 | C11: Washrooms & Toilets | D11: Admin Block Washrooms | E11: Black | F11: 200 | G11: CT-WR-02 | H11: STP | I11: Formula
A12: 9 | C12: Hostels | D12: Hostel A (Boys) — Bathrooms | E12: Grey | F12: 600 | G12: CT-HA-GR | H12: STP | I12: Estimate
A13: 10 | C13: Hostels | D13: Hostel A (Boys) — Toilets | E13: Black | F13: 400 | G13: CT-HA-BK | H13: STP | I13: Formula
A14: 11 | C14: Hostels | D14: Hostel B (Boys) | E14: Grey | F14: 500 | G14: CT-HB-GR | H14: STP | I14: Estimate
A15: 12 | C15: Hostels | D15: Hostel C (Girls) — All | E15: Grey | F15: 700 | G15: CT-HC | H15: STP | I15: Estimate | J15: Mixed grey+black
A16: 13 | C16: Hostels | D16: Hostel Laundry | E16: Grey | F16: 300 | G16: CT-HL | H16: STP | I16: Estimate | J16: Detergent-laden
A17: 14 | C17: RO Plant | D17: RO Plant Reject Water | E17: RO | F17: 800 | G17: CT-RO-01 | H17: ETP | I17: Meter | J17: 60–70% of RO input
A18: 15 | C18: Gardening | D18: Garden Overflow / Wash | E18: Grey | F18: 100 | G18: Recharge Pit | H18: Recharge Pit | I18: Estimate | J18: Seasonal variation
A19: 16
A20: 17
A21: 18
A22: 19
A23: 20
A24: 21
A25: 22
A26: 23
A27: 24
A28: 25
A29: 26
A30: 27
... A53: 50
A54: Source-Wise Generation Summary (Auto-Calculated)
C55: Source Category | F55: Volume (L/day) | H55: % of Total
A56: Academic Dept | F56: =SUMPRODUCT((C4:C53="Academic Dept")*F4:F53) -> 630 | H56: =IF(SUM(F4:F53)>0,F56/SUM(F4:F53)*100,0) -> 10.623946
A57: Canteen & Mess | F57: =SUMPRODUCT((C4:C53="Canteen & Mess")*F4:F53) -> 900 | H57: =IF(SUM(F4:F53)>0,F57/SUM(F4:F53)*100,0) -> 15.177066
A58: Washrooms & Toilets | F58: =SUMPRODUCT((C4:C53="Washrooms & Toilets")*F4:F53) -> 1000 | H58: =IF(SUM(F4:F53)>0,F58/SUM(F4:F53)*100,0) -> 16.863406
A59: Hostels | F59: =SUMPRODUCT((C4:C53="Hostels")*F4:F53) -> 2500 | H59: =IF(SUM(F4:F53)>0,F59/SUM(F4:F53)*100,0) -> 42.158516
A60: RO Plant | F60: =SUMPRODUCT((C4:C53="RO Plant")*F4:F53) -> 800 | H60: =IF(SUM(F4:F53)>0,F60/SUM(F4:F53)*100,0) -> 13.490725
A61: Gardening | F61: =SUMPRODUCT((C4:C53="Gardening")*F4:F53) -> 100 | H61: =IF(SUM(F4:F53)>0,F61/SUM(F4:F53)*100,0) -> 1.6863406
A63: Wastewater Type Summary
...

Sheet 3. Treatment Plan
A1: Treatment Plant Register — STP & ETP Capacity, Inflow & Treated Output
A2: Inflow auto-calculated from Sources Log | Treated volume = min(capacity, inflow) | Efficiency tracked
A3: Plant ID | B3: Plant Type (STP/ETP) | C3: Rated Capacity (KLD) | D3: Rated Capacity (L/day) [AUTO] | E3: Inflow (L/day) [AUTO from Sources] | F3: Treated Volume (L/day) [AUTO] | G3: Treatment Efficiency (%) | H3: Last Service Date | I3: Next Service Due | J3: Remarks
A4: STP-1 | B4: STP | C4: 100 | D4: =C4*1000 -> 100000 | E4: =SUMPRODUCT(('2. Sources Log'!H4:H53=B4)*('2. Sources Log'!F4:F53)) -> 4880 | F4: =MIN(D4,E4) -> 4880 | J4: Main campus STP — activated sludge process
A5: STP-2 | B5: STP | C5: 50 | D5: =C5*1000 -> 50000 | E5: =SUMPRODUCT(('2. Sources Log'!H4:H53=B5)*('2. Sources Log'!F4:F53)) -> 4880 | F5: =MIN(D5,E5) -> 4880 | J5: Hostel block STP — MBBR technology
A6: ETP-1 | B6: ETP | C6: 50 | D6: =C6*1000 -> 50000 | E6: =SUMPRODUCT(('2. Sources Log'!H4:H53=B6)*('2. Sources Log'!F4:F53)) -> 950 | F6: =MIN(D6,E6) -> 950 | J6: For RO reject, lab waste, canteen grease-trap effluent
A7: ETP-2 | B7: ETP | C7: 20 | D7: =C7*1000 -> 20000 | E7: =SUMPRODUCT(('2. Sources Log'!H4:H53=B7)*('2. Sources Log'!F4:F53)) -> 950 | F7: =MIN(D7,E7) -> 950 | J7: Backup / overflow ETP
D8: =IF(C8>0,C8*1000,0) -> 0 | E8: =IF(B8<>"",SUMPRODUCT(('2. Sources Log'!H4:H53=B8)*('2. Sources Log'!F4:F53)),0) -> 0 | F8: =IF(AND(D8>0,E8>0),MIN(D8,E8),0) -> 0
D9: =IF(C9>0,C9*1000,0) -> 0 | E9: =IF(B9<>"",SUMPRODUCT(('2. Sources Log'!H4:H53=B9)*('2. Sources Log'!F4:F53)),0) -> 0 | F9: =IF(AND(D9>0,E9>0),MIN(D9,E9),0) -> 0
D10: =IF(C10>0,C10*1000,0) -> 0 | E10: =IF(B10<>"",SUMPRODUCT(('2. Sources Log'!H4:H53=B10)*('2. Sources Log'!F4:F53)),0) -> 0 | F10: =IF(AND(D10>0,E10>0),MIN(D10,E10),0) -> 0
D11: =IF(C11>0,C11*1000,0) -> 0 | E11: =IF(B11<>"",SUMPRODUCT(('2. Sources Log'!H4:H53=B11)*('2. Sources Log'!F4:F53)),0) -> 0 | F11: =IF(AND(D11>0,E11>0),MIN(D11,E11),0) -> 0
A12: Treatment Totals
A13: TOTAL | D13: =SUM(D4:D11) -> 220000 | E13: =SUM(E4:E11) -> 11660 | F13: =SUM(F4:F11) -> 11660
A14: Total Capacity (KLD) | D14: =SUM(C4:C11) -> 220
A15: Total Inflow (KLD) | D15: =E13/1000 -> 11.66
A16: Total Treated (KLD) | D16: =F13/1000 -> 11.66
A17: Capacity Utilization (%) | D17: =IF(D13>0,E13/D13*100,0) -> 5.3
A18: Overflow / Untreated (L/day) | D18: =IF(E13>D13,E13-D13,0) -> 0

Sheet 4. Reuse Plan
A1: Treated Water Reuse Plan — Application & Distribution
A2: Assign treated STP/ETP output to reuse applications | Track reuse volume vs treated volume
A3: S.No. | B3: Reuse Application | C3: Location / Block | D3: Source Plant (STP-1/ETP-1/etc.) | E3: Assigned Volume (L/day) | F3: Distribution / Pipeline Ref | G3: Quality Requirement | H3: Remarks
A4: 1 | B4: Gardening / Landscaping Irrigation | C4: Campus gardens, lawns, nursery | D4: STP-1 | F4: Pipeline P-GDN-01 | G4: pH 6.5–8.5, BOD <20
A5: 2 | B5: Toilet Flushing | C5: Hostel A & B flush tanks | D5: STP-1 | F5: Pipeline P-FLUSH-01 | G5: pH 6.5–8.5, no odour | H5: Dual plumbing required
A6: 3 | B6: Toilet Flushing | C6: Academic Block washrooms | D6: STP-2 | F6: Pipeline P-FLUSH-02
A7: 4 | B7: Floor Cleaning / Mopping | C7: All buildings general cleaning | D7: STP-1 | F7: Tanker / manual | G7: Non-potable standard
A8: 5 | B8: Cooling Tower Makeup | C8: Central AC plant | D8: ETP-1 | F8: Pipeline P-COOL-01 | G8: Low TDS preferred | H8: If applicable
A9: 6 | B9: Construction Use | C9: New building projects on campus | D9: STP-1 | F9: Tanker | G9: Non-potable | H9: Seasonal
A10: 7 | B10: Vehicle Washing | C10: Transport / parking area | D10: ETP-1 | F10: Manual | G10: Non-potable
A11: 8 | B11: Sports Ground / Playground | C11: Cricket pitch, football ground | D11: STP-1 | F11: Sprinkler S-SPT-01
A12: 9
A13: 10
A14: 11
A15: 12
A16: 13
A17: 14
A18: 15
A19: 16
A20: 17
A21: 18
A22: 19
A23: 20
A24: Reuse Summary
A25: TOTAL REUSE ASSIGNED (L/day) | E25: =SUM(E4:E23) -> 0
A26: Total Reuse (KLD) | E26: =E25/1000 -> 0
A27: Treated Volume Available (L/day) | E27: ='3. Treatment Plan'!F13 -> 11660
A28: Reuse as % of Treated | E28: =IF(E27>0,E25/E27*100,0) -> 0
A29: Surplus Treated (Unassigned) | E29: =E27-E25 -> 11660

Sheet 5. Dashboard Summary
A1: Wastewater Audit Dashboard — Auto-Calculated KPIs
A2: All values auto-linked from Sources Log, Treatment Plan & Reuse Plan
A3: S.No. | B3: KPI / Metric | C3: Value | D3: Unit | E3: Formula Source | F3: Target | G3: Status
A4: 1 | B4: Total Wastewater Generated | C4: ='2. Sources Log'!F74 -> 5930 | D4: L/day | E4: Sources Log Grand Total
A5: 2 | B5: Generated (KLD) | C5: ='2. Sources Log'!F74/1000 -> 5.93 | D5: KLD
A6: 3 | B6: Grey Water Generated | C6: ='2. Sources Log'!F64 -> 3580 | D6: L/day | E6: Type = Grey
A7: 4 | B7: Black Water Generated | C7: ='2. Sources Log'!F65 -> 1400 | D7: L/day | E7: Type = Black
A8: 5 | B8: RO Reject Generated | C8: ='2. Sources Log'!F66 -> 800 | D8: L/day | E8: Type = RO
A9: 6 | B9: Lab Wastewater Generated | C9: ='2. Sources Log'!F67 -> 150 | D9: L/day | E9: Type = Lab
A10: 7 | B10: Sent to STP (L/day) | C10: ='2. Sources Log'!F70 -> 4880 | D10: L/day | E10: Route = STP
A11: 8 | B11: Sent to ETP (L/day) | C11: ='2. Sources Log'!F71 -> 950 | D11: L/day | E11: Route = ETP
A12: 9 | B12: Total Treatment Capacity (L/day) | C12: ='3. Treatment Plan'!D13 -> 220000 | D12: L/day | E12: Treatment Plan
A13: 10 | B13: Total Treated Volume (L/day) | C13: ='3. Treatment Plan'!F13 -> 11660 | D13: L/day | E13: Treatment Plan
A14: 11 | B14: Capacity Utilization (%) | C14: =IF(C12>0,C13/C12*100,0) -> 5.3 | D14: % | E14: Treated/Capacity
A15: 12 | B15: Total Reuse Assigned (L/day) | C15: ='4. Reuse Plan'!E25 -> 0 | D15: L/day | E15: Reuse Plan
A16: 13 | B16: REUSE % OF GENERATED | C16: =IF(C4>0,C15/C4*100,0) -> 0 | D16: % | E16: Reuse/Generated — KEY KPI
A17: 14 | B17: REUSE % OF TREATED | C17: =IF(C13>0,C15/C13*100,0) -> 0 | D17: % | E17: Reuse/Treated
A18: 15 | B18: Untreated / Overflow (L/day) | C18: =IF(C4>C13,C4-C13,0) -> 0 | D18: L/day | E18: Generated−Treated
A19: 16 | B19: Unassigned Treated (L/day) | C19: =IF(C13>C15,C13-C15,0) -> 11660 | D19: L/day | E19: Treated−Reused

Sheet 6. YoY Trend
A1: Wastewater Management — 5-Year Trend
A2: Track generation, treatment, and reuse progress for NAAC / Green Audit
A3: S.No. | B3: Parameter | C3: Unit | D3: Year 1 | E3: Year 2 | F3: Year 3 | G3: Year 4 | H3: Year 5 | I3: 5-Year Change | J3: Growth (%) | K3: Trend
A4: 1 | B4: Total Generated (KLD) | I4: =IF(AND(D4>0,H4>0),H4-D4,0) -> 0 | J4: =IFERROR(IF(D4>0,(H4-D4)/D4*100,0),0) -> 0 | K4: =IF(I4>0,"Improving",IF(I4=0,"Stable","Declining")) -> Stable
A5: 2 | B5: Total Treated (KLD) | I5: =IF(AND(D5>0,H5>0),H5-D5,0) -> 0 | J5: =IFERROR(IF(D5>0,(H5-D5)/D5*100,0),0) -> 0 | K5: =IF(I5>0,"Improving",IF(I5=0,"Stable","Declining")) -> Stable
A6: 3 | B6: Total Reused (KLD) | I6: =IF(AND(D6>0,H6>0),H6-D6,0) -> 0 | J6: =IFERROR(IF(D6>0,(H6-D6)/D6*100,0),0) -> 0 | K6: =IF(I6>0,"Improving",IF(I6=0,"Stable","Declining")) -> Stable
A7: 4 | B7: Reuse % of Generated | I7: =IF(AND(D7>0,H7>0),H7-D7,0) -> 0 | J7: =IFERROR(IF(D7>0,(H7-D7)/D7*100,0),0) -> 0 | K7: =IF(I7>0,"Improving",IF(I7=0,"Stable","Declining")) -> Stable
A8: 5 | B8: STP Capacity (KLD) | I8: =IF(AND(D8>0,H8>0),H8-D8,0) -> 0 | J8: =IFERROR(IF(D8>0,(H8-D8)/D8*100,0),0) -> 0 | K8: =IF(I8>0,"Improving",IF(I8=0,"Stable","Declining")) -> Stable
A9: 6 | B9: ETP Capacity (KLD) | I9: =IF(AND(D9>0,H9>0),H9-D9,0) -> 0 | J9: =IFERROR(IF(D9>0,(H9-D9)/D9*100,0),0) -> 0 | K9: =IF(I9>0,"Improving",IF(I9=0,"Stable","Declining")) -> Stable
A10: 7 | B10: Capacity Utilization (%) | I10: =IF(AND(D10>0,H10>0),H10-D10,0) -> 0 | J10: =IFERROR(IF(D10>0,(H10-D10)/D10*100,0),0) -> 0 | K10: =IF(I10>0,"Improving",IF(I10=0,"Stable","Declining")) -> Stable
A11: 8 | B11: Sludge Composted (Tonnes/yr) | I11: =IF(AND(D11>0,H11>0),H11-D11,0) -> 0 | J11: =IFERROR(IF(D11>0,(H11-D11)/D11*100,0),0) -> 0 | K11: =IF(I11>0,"Improving",IF(I11=0,"Stable","Declining")) -> Stable

Sheet 7. Audit Checklist
A1: Wastewater Audit — Compliance Checklist (NAAC 7.1.4 / CPCB / Green Audit)
A2: Evidence readiness for accreditation, pollution control board, sustainability reporting
A3: # | B3: Audit Item | C3: Requirement / Description | D3: Status (✓/✗/IP) | E3: Date | F3: Reviewer
A4: 1 | B4: All wastewater sources identified | C4: Every source (academic, canteen, washrooms, hostels, RO, gardening) logged
A5: 2 | B5: Volumes estimated or metered | C5: L/day per source documented; meter-based preferred, formula-based acceptable
A6: 3 | B6: Wastewater type classified | C6: Grey / Black / RO / Lab classification assigned per source
A7: 4 | B7: Routing documented | C7: Every source routed to STP, ETP, or recharge pit; documented
A8: 5 | B8: Source-wise summary auto-calculated | C8: Category totals (academic, canteen, etc.) and type totals auto-computed
A9: 6 | B9: STP capacity documented | C9: Rated capacity (KLD), technology type, commissioning date documented
A10: 7 | B10: ETP capacity documented | C10: Rated capacity, input sources, treatment process documented
A11: 8 | B11: Inflow auto-linked from sources | C11: Treatment plant inflow = sum of sources routed to it; auto-calculated
A12: 9 | B12: Treated volume computed | C12: Treated = min(capacity, inflow); documented per plant
A13: 10 | B13: Capacity utilization tracked | C13: % utilization = inflow/capacity; overcapacity flagged
A14: 11 | B14: Reuse plan documented | C14: Every treated water application: gardening, flushing, cleaning, cooling assigned
A15: 12 | B15: Reuse % of generated computed | C15: KEY KPI: total reuse ÷ total generated × 100; auto-calculated
... A23: 20 | B23: NAAC 7.1.4 / Green Audit ready | C23: Complete documentation package for water management criterion
